size = 6 6 6
scale = 0.125
origin = -y
material lighting = flat, roughness = 0.9, deform = 1
  colors = C:#b98a52 E:#8a6236
voxels
EEEEEE ECCCCE ECCCCE ECCCCE ECCCCE EEEEEE
ECCCCE CCCCCC CCCCCC CCCCCC CCCCCC ECCCCE
ECCCCE CCCCCC CCCCCC CCCCCC CCCCCC ECCCCE
ECCCCE CCCCCC CCCCCC CCCCCC CCCCCC ECCCCE
ECCCCE CCCCCC CCCCCC CCCCCC CCCCCC ECCCCE
EEEEEE ECCCCE ECCCCE ECCCCE ECCCCE EEEEEE
