size = 7 11 7
scale = 0.125
origin = -y
material lighting = smooth, roughness = 0.1, emissive = #8fd8ff 0.4, deform = 1
  colors = A:#8fd8ff B:#c7b2ff
voxels
------- ------- ------- ------- ------- ------- ------- ------- ------- ------- -------
-A----- -A----- ------- ------- ------- ------- ------- ------- ------- ------- -------
BAAB--- AABA--- -B-A--- -A-B--- -A----- -B----- ------- ------- ------- ------- -------
-AABAA- -ABAAB- --AABA- --ABA-- ---A--- ---A--- ---B--- ---A--- ---A--- ---B--- -------
--ABAAB --BAABA ---ABAA ---B-A- -----B- -----A- -----A- ------- ------- ------- -------
-AAB-A- -ABA-B- --A--A- --A---- --B---- ------- ------- ------- ------- ------- -------
--A---- --B---- ------- ------- ------- ------- ------- ------- ------- ------- -------
