size = 8 8 8
scale = 0.125
origin = -y
material lighting = smooth, roughness = 0.9, deform = 1
  colors = S:#5e9e4e
material lighting = smooth, roughness = 1, deform = 6
  colors = P:#f2a1c4 Y:#ffd65c
voxels
-------- -------- -------- -------- -------- -------- -------- --------
-------- -------- -------- -------- -------- -------- ---PP--- ---PP---
-------- -------- -------- -------- -------- -------- --PPPP-- --PPPP--
---SS--- ---SS--- ---SS--- ---SS--- ---SS--- ---SS--- -PPYYPP- -PPYYPP-
---SS--- ---SS--- ---SS--- ---SS--- ---SS--- ---SS--- -PPYYPP- -PPYYPP-
-------- -------- -------- -------- -------- -------- --PPPP-- --PPPP--
-------- -------- -------- -------- -------- -------- ---PP--- ---PP---
-------- -------- -------- -------- -------- -------- -------- --------
