size = 11 18 11
scale = 0.125
origin = -y
material lighting = smooth, roughness = 0.9, deform = 1
  colors = T:#5e3f2c
material lighting = smooth, roughness = 0.9, deform = 4
  colors = P:#3f7a4f Q:#356a44
voxels
----------- ----------- ---QPPPP--- ----PPP---- ----------- ----------- ----------- ----------- ----------- ----------- ----------- ----------- ----------- ----------- ----------- ----------- ----------- -----------
----------- ----------- -PQPPPPQPP- --PPPPQPP-- ---PPQPP--- ----------- ----PPP---- ----------- ----------- ----------- ----------- ----------- ----------- ----------- ----------- ----------- ----------- -----------
----------- ----------- -QPPPPQPPP- -PPPPQPPPP- --PPQPPPP-- ---QPPPP--- --QPPPPQP-- ---PPPQP--- -----Q----- ----------- -----P----- ----------- ----------- ----------- ----------- ----------- ----------- -----------
----------- ----------- QPPPPQPPPPQ -PPPQPPPPQ- -PPQPPPPQP- --QPPPPQP-- --PPPPQPP-- --PPPQPPP-- ---PQPPP--- ----PPP---- ---PPPPQ--- ----PPQ---- ----------- ----------- ----------- ----------- ----------- -----------
----TTT---- ----TTT---- PPPPTTTPPQP PPPQTTTPQPP -PQPPPPQPP- --PPPPQPP-- -PPPPQPPPP- --PPQPPPP-- ---QPPPP--- ---PPPPQ--- ---PPPQP--- ---PPQPP--- ----QPP---- -----P----- ----PPP---- ----------- ----------- -----------
----TTT---- ----TTT---- PPPQTTTPQPP PPQPTTTQPPP -QPPPPQPPP- --PPPQPPP-- -PPPQPPPPQ- --PQPPPPQ-- --QPPPPQP-- ---PPPQP--- --PPPQPPP-- ---PQPPP--- ----PPP---- ----PPP---- ----PPQ---- -----Q----- -----P----- -----------
----TTT---- ----TTT---- PPQPTTTQPPP PQPPTTTPPPP -PPPPQPPPP- --PPQPPPP-- -PPQPPPPQP- --QPPPPQP-- ---PPPQP--- ---PPQPP--- ---PQPPP--- ---QPPPP--- ----PPP---- -----P----- ----PQP---- ----------- ----------- -----------
----------- ----------- PQPPPPQPPPP -PPPPQPPPP- -PPPQPPPPQ- --PQPPPPQ-- --QPPPPQP-- --PPPPQPP-- ---PPQPP--- ----QPP---- ---QPPPP--- ----PPP---- ----------- ----------- ----------- ----------- ----------- -----------
----------- ----------- -PPPPQPPPP- -PPPQPPPPQ- --PQPPPPQ-- ---PPPPQ--- --PPPPQPP-- ---PPQPP--- -----P----- ----------- -----P----- ----------- ----------- ----------- ----------- ----------- ----------- -----------
----------- ----------- -PPPQPPPPQ- --PQPPPPQ-- ---PPPPQ--- ----------- ----PQP---- ----------- ----------- ----------- ----------- ----------- ----------- ----------- ----------- ----------- ----------- -----------
----------- ----------- ---QPPPP--- ----PPP---- ----------- ----------- ----------- ----------- ----------- ----------- ----------- ----------- ----------- ----------- ----------- ----------- ----------- -----------
